[2024-09-26 21:32:24,106] INFO _log() L97   127.0.0.1 - - [26/Sep/2024 21:32:24] "GET /produto HTTP/1.1" 200 - - call_trace=C:\Users\Bruno\AppData\Local\Packages\PythonSoftwareFoundation.Python.3.12_qbz5n2kfra8p0\LocalCache\local-packages\Python312\site-packages\werkzeug\_internal.py L97  
[2024-09-26 21:32:39,432] INFO _log() L97   127.0.0.1 - - [26/Sep/2024 21:32:39] "GET /cliente HTTP/1.1" 200 - - call_trace=C:\Users\Bruno\AppData\Local\Packages\PythonSoftwareFoundation.Python.3.12_qbz5n2kfra8p0\LocalCache\local-packages\Python312\site-packages\werkzeug\_internal.py L97  
[2024-09-26 21:32:39,433] INFO _log() L97   127.0.0.1 - - [26/Sep/2024 21:32:39] "GET /produto/?nome=Arroz HTTP/1.1" 200 - - call_trace=C:\Users\Bruno\AppData\Local\Packages\PythonSoftwareFoundation.Python.3.12_qbz5n2kfra8p0\LocalCache\local-packages\Python312\site-packages\werkzeug\_internal.py L97  
[2024-09-26 21:32:39,445] INFO _log() L97   127.0.0.1 - - [26/Sep/2024 21:32:39] "GET /produto HTTP/1.1" 200 - - call_trace=C:\Users\Bruno\AppData\Local\Packages\PythonSoftwareFoundation.Python.3.12_qbz5n2kfra8p0\LocalCache\local-packages\Python312\site-packages\werkzeug\_internal.py L97  
[2024-09-26 21:32:39,448] INFO _log() L97   127.0.0.1 - - [26/Sep/2024 21:32:39] "GET /produto HTTP/1.1" 200 - - call_trace=C:\Users\Bruno\AppData\Local\Packages\PythonSoftwareFoundation.Python.3.12_qbz5n2kfra8p0\LocalCache\local-packages\Python312\site-packages\werkzeug\_internal.py L97  
[2024-09-26 21:32:39,455] INFO _log() L97   127.0.0.1 - - [26/Sep/2024 21:32:39] "GET /cliente HTTP/1.1" 200 - - call_trace=C:\Users\Bruno\AppData\Local\Packages\PythonSoftwareFoundation.Python.3.12_qbz5n2kfra8p0\LocalCache\local-packages\Python312\site-packages\werkzeug\_internal.py L97  
[2024-09-26 21:32:39,490] INFO _log() L97   127.0.0.1 - - [26/Sep/2024 21:32:39] "GET /produto HTTP/1.1" 200 - - call_trace=C:\Users\Bruno\AppData\Local\Packages\PythonSoftwareFoundation.Python.3.12_qbz5n2kfra8p0\LocalCache\local-packages\Python312\site-packages\werkzeug\_internal.py L97  
[2024-09-26 21:33:11,185] ERROR log_exception() L838  Exception on /cliente [GET] - call_trace=C:\Users\Bruno\AppData\Local\Packages\PythonSoftwareFoundation.Python.3.12_qbz5n2kfra8p0\LocalCache\local-packages\Python312\site-packages\flask\app.py L838 
Traceback (most recent call last):
  File "C:\Users\Bruno\AppData\Local\Packages\PythonSoftwareFoundation.Python.3.12_qbz5n2kfra8p0\LocalCache\local-packages\Python312\site-packages\flask\app.py", line 1473, in wsgi_app
    response = self.full_dispatch_request()
               ^^^^^^^^^^^^^^^^^^^^^^^^^^^^
  File "C:\Users\Bruno\AppData\Local\Packages\PythonSoftwareFoundation.Python.3.12_qbz5n2kfra8p0\LocalCache\local-packages\Python312\site-packages\flask\app.py", line 883, in full_dispatch_request
    return self.finalize_request(rv)
           ^^^^^^^^^^^^^^^^^^^^^^^^^
  File "C:\Users\Bruno\AppData\Local\Packages\PythonSoftwareFoundation.Python.3.12_qbz5n2kfra8p0\LocalCache\local-packages\Python312\site-packages\flask\app.py", line 902, in finalize_request
    response = self.make_response(rv)
               ^^^^^^^^^^^^^^^^^^^^^^
  File "C:\Users\Bruno\AppData\Local\Packages\PythonSoftwareFoundation.Python.3.12_qbz5n2kfra8p0\LocalCache\local-packages\Python312\site-packages\flask\app.py", line 1193, in make_response
    rv = self.json.response(rv)
         ^^^^^^^^^^^^^^^^^^^^^^
  File "C:\Users\Bruno\AppData\Local\Packages\PythonSoftwareFoundation.Python.3.12_qbz5n2kfra8p0\LocalCache\local-packages\Python312\site-packages\flask\json\provider.py", line 214, in response
    f"{self.dumps(obj, **dump_args)}\n", mimetype=self.mimetype
       ^^^^^^^^^^^^^^^^^^^^^^^^^^^^
  File "C:\Users\Bruno\AppData\Local\Packages\PythonSoftwareFoundation.Python.3.12_qbz5n2kfra8p0\LocalCache\local-packages\Python312\site-packages\flask\json\provider.py", line 179, in dumps
    return json.dumps(obj, **kwargs)
           ^^^^^^^^^^^^^^^^^^^^^^^^^
  File "C:\Program Files\WindowsApps\PythonSoftwareFoundation.Python.3.12_3.12.1776.0_x64__qbz5n2kfra8p0\Lib\json\__init__.py", line 238, in dumps
    **kw).encode(obj)
          ^^^^^^^^^^^
  File "C:\Program Files\WindowsApps\PythonSoftwareFoundation.Python.3.12_3.12.1776.0_x64__qbz5n2kfra8p0\Lib\json\encoder.py", line 200, in encode
    chunks = self.iterencode(o, _one_shot=True)
             ^^^^^^^^^^^^^^^^^^^^^^^^^^^^^^^^^^
  File "C:\Program Files\WindowsApps\PythonSoftwareFoundation.Python.3.12_3.12.1776.0_x64__qbz5n2kfra8p0\Lib\json\encoder.py", line 258, in iterencode
    return _iterencode(o, 0)
           ^^^^^^^^^^^^^^^^^
  File "C:\Users\Bruno\AppData\Local\Packages\PythonSoftwareFoundation.Python.3.12_qbz5n2kfra8p0\LocalCache\local-packages\Python312\site-packages\flask\json\provider.py", line 121, in _default
    raise TypeError(f"Object of type {type(o).__name__} is not JSON serializable")
TypeError: Object of type TimeoutError is not JSON serializable
